Workbook

Sheet Dataset_con_Errores
A1: IdVenta | B1: Fecha | C1: Cliente | D1: Ciudad | E1: Producto | F1: Cantidad | G1: PrecioUnitario | H1: TotalVenta
A2: 1 | B2: 05/03/2026 | C2: Ana Torres | D2: Medellin | F2: 0 | G2: 1500 | H2: 0 | K2: =IFERROR(DATE(VALUE(RIGHT(B2,4)),VALUE(MID(B2,4,2)),VALUE(LEFT(B2,2))),B2) -> 46086 | L2: =+IF(ISNUMBER(K2),"OK","ERROR") -> OK
A3: 2 | B3: 20/03/2026 | D3: medellín | E3: Laptop | F3: -3 | G3: 50 | H3: -150 | K3: =IFERROR(DATE(VALUE(RIGHT(B3,4)),VALUE(MID(B3,4,2)),VALUE(LEFT(B3,2))),B3) -> 46101 | L3: =+IF(ISNUMBER(K3),"OK","ERROR") -> OK
A4: 3 | B4: 31-Jan-26 | C4: juan perez | D4: bogotá | E4: Mouse | F4: 0 | G4: 1500 | H4: 97 | K4: =IFERROR(DATE(VALUE(RIGHT(B4,4)),VALUE(MID(B4,4,2)),VALUE(LEFT(B4,2))),B4) -> 31-Jan-26 | L4: =+IF(ISNUMBER(K4),"OK","ERROR") -> ERROR
A5: 4 | B5: 02/01/2026 | C5: Carlos Ruiz | D5: Bogota | E5: Monitor | F5: 3 | G5: 1500 | H5: 4500 | K5: =IFERROR(DATE(VALUE(RIGHT(B5,4)),VALUE(MID(B5,4,2)),VALUE(LEFT(B5,2))),B5) -> 46024 | L5: =+IF(ISNUMBER(K5),"OK","ERROR") -> OK
A6: 5 | B6: 2026-03-06 | C6: MARIA LOPEZ | D6: medellín | F6: -2 | G6: 50 | H6: -10 | K6: =IFERROR(DATE(VALUE(RIGHT(B6,4)),VALUE(MID(B6,4,2)),VALUE(LEFT(B6,2))),B6) -> 2026-03-06 | L6: =+IF(ISNUMBER(K6),"OK","ERROR") -> ERROR
A7: 6 | B7: 19/03/2026 | C7: MARIA LOPEZ | D7: Medellin | E7: Monitor | F7: 0 | G7: 1500 | H7: 0 | K7: =IFERROR(DATE(VALUE(RIGHT(B7,4)),VALUE(MID(B7,4,2)),VALUE(LEFT(B7,2))),B7) -> 46100 | L7: =+IF(ISNUMBER(K7),"OK","ERROR") -> OK
A8: 7 | B8: 2026-03-01 | C8: Ana Torres | D8: Bogotá | F8: -2 | G8: 1500 | H8: -3000 | K8: =IFERROR(DATE(VALUE(RIGHT(B8,4)),VALUE(MID(B8,4,2)),VALUE(LEFT(B8,2))),B8) -> 2026-03-01 | L8: =+IF(ISNUMBER(K8),"OK","ERROR") -> ERROR
A9: 8 | B9: 2026-02-14 | C9: MARIA LOPEZ | D9: Bogota | E9: Teclado | F9: -1 | G9: 50 | H9: -50 | K9: =IFERROR(DATE(VALUE(RIGHT(B9,4)),VALUE(MID(B9,4,2)),VALUE(LEFT(B9,2))),B9) -> 2026-02-14
A10: 9 | B10: 12-Mar-26 | C10: Ana Torres | D10: Medellin | E10: Laptop | F10: 2 | G10: 80 | H10: 160 | K10: =IFERROR(DATE(VALUE(RIGHT(B10,4)),VALUE(MID(B10,4,2)),VALUE(LEFT(B10,2))),B10) -> 12-Mar-26
A11: 10 | B11: 2026-02-01 | C11: juan perez | D11: bogotá | F11: 0 | G11: 80 | H11: 0 | K11: =IFERROR(DATE(VALUE(RIGHT(B11,4)),VALUE(MID(B11,4,2)),VALUE(LEFT(B11,2))),B11) -> 2026-02-01
A12: 11 | B12: 29/03/2026 | C12: MARIA LOPEZ | D12: Bogotá | F12: -2 | G12: 700 | H12: -1309 | K12: =IFERROR(DATE(VALUE(RIGHT(B12,4)),VALUE(MID(B12,4,2)),VALUE(LEFT(B12,2))),B12) -> 46110
A13: 12 | B13: 29-Jan-26 | C13: Carlos Ruiz | D13: bogotá | E13: Laptop | F13: 0 | G13: 700 | H13: 0 | K13: =IFERROR(DATE(VALUE(RIGHT(B13,4)),VALUE(MID(B13,4,2)),VALUE(LEFT(B13,2))),B13) -> 29-Jan-26
A14: 13 | B14: 2026-01-13 | C14: juan perez | D14: bogotá | E14: Laptop | F14: 0 | G14: 50 | H14: 0
A15: 14 | B15: 2026-03-09 | C15: MARIA LOPEZ | D15: Medellin | E15: Mouse | F15: -2 | G15: 80 | H15: -160
A16: 15 | B16: 2026-01-14 | D16: bogotá | E16: Teclado | F16: 5 | G16: 80 | H16: 400
A17: 16 | B17: 2026-01-15 | C17: Carlos Ruiz | D17: Medellin | F17: 0 | G17: 1500 | H17: 0
A18: 17 | B18: 09-Feb-26 | C18: Ana Torres | D18: medellín | E18: Teclado | F18: -3 | G18: 1500 | H18: -4473
A19: 18 | B19: 05-Mar-26 | C19: MARIA LOPEZ | D19: Bogotá | E19: Laptop | F19: 0 | G19: 700 | H19: 0
A20: 19 | B20: 11/02/2026 | D20: Bogota | E20: Teclado | F20: 4 | G20: 700 | H20: 2800
A21: 20 | B21: 2026-01-08 | C21: Ana Torres | D21: Medellin | F21: 4 | G21: 700 | H21: 2800
A22: 21 | B22: 27-Mar-26 | C22: MARIA LOPEZ | D22: Bogota | F22: 0 | G22: 700 | H22: 0
A23: 22 | B23: 07/01/2026 | D23: Medellin | F23: -2 | G23: 700 | H23: -1400
A24: 23 | B24: 13-Jan-26 | C24: Carlos Ruiz | D24: Medellin | E24: Monitor | F24: 5 | G24: 700 | H24: 3522
A25: 24 | B25: 07/03/2026 | C25: Carlos Ruiz | D25: Bogotá | E25: Laptop | F25: -3 | G25: 80 | H25: -240
A26: 25 | B26: 31-Jan-26 | C26: MARIA LOPEZ | D26: Bogotá | E26: Teclado | F26: 0 | G26: 50 | H26: 0
A27: 26 | B27: 13-Feb-26 | D27: Bogotá | F27: 5 | G27: 80 | H27: 400
A28: 27 | B28: 09/01/2026 | C28: Carlos Ruiz | D28: Bogota | F28: -1 | G28: 1500 | H28: -1500
A29: 28 | B29: 25/02/2026 | C29: Ana Torres | D29: bogotá | E29: Mouse | F29: -3 | G29: 1500 | H29: -4500
A30: 29 | B30: 2026-01-22 | C30: juan perez | D30: Bogotá | E30: Mouse | F30: 5 | G30: 700 | H30: 3529
A31: 30 | B31: 09-Jan-26 | C31: MARIA LOPEZ | D31: Medellin | E31: Laptop | F31: 0 | G31: 80 | H31: 0
A32: 31 | B32: 14/02/2026 | C32: Carlos Ruiz | D32: medellín | E32: Laptop | F32: -1 | G32: 1500 | H32: -1500
A33: 32 | B33: 2026-02-19 | C33: MARIA LOPEZ | D33: Bogotá | E33: Monitor | F33: 3 | G33: 1500 | H33: 4521
A34: 33 | B34: 16-Feb-26 | C34: MARIA LOPEZ | D34: Bogota | E34: Mouse | F34: -1 | G34: 1500 | H34: -1500
A35: 34 | B35: 2026-02-04 | C35: Ana Torres | D35: bogotá | E35: Monitor | F35: -3 | G35: 50 | H35: -57
A36: 35 | B36: 2026-03-15 | C36: juan perez | D36: Bogotá | E36: Teclado | F36: -1 | G36: 80 | H36: -80
A37: 36 | B37: 22-Mar-26 | C37: Ana Torres | D37: medellín | F37: 2 | G37: 50 | H37: 100
A38: 37 | B38: 25-Jan-26 | D38: Bogotá | F38: -2 | G38: 1500 | H38: -3000
A39: 38 | B39: 05-Jan-26 | C39: juan perez | D39: Bogotá | F39: 0 | G39: 80 | H39: 16
A40: 39 | B40: 13-Mar-26 | D40: bogotá | E40: Laptop | F40: -3 | G40: 80 | H40: -240
...

Sheet Validaciones_Formato
A1: IdVenta | B1: Fecha | C1: Cliente | D1: Ciudad | E1: Producto | F1: Cantidad | G1: PrecioUnitario | H1: TotalVenta
A2: 1 | B2: 05/03/2026 | C2: Ana Torres | D2: Medellin | F2: 0 | G2: 1500 | H2: 0
A3: 2 | B3: 20/03/2026 | D3: medellín | E3: Laptop | F3: -3 | G3: 50 | H3: -150
A4: 3 | B4: 31-Jan-26 | C4: juan perez | D4: bogotá | E4: Mouse | F4: 0 | G4: 1500 | H4: 97
A5: 4 | B5: 02/01/2026 | C5: Carlos Ruiz | D5: Bogota | E5: Monitor | F5: 3 | G5: 1500 | H5: 4500
A6: 5 | B6: 2026-03-06 | C6: MARIA LOPEZ | D6: medellín | F6: -2 | G6: 50 | H6: -10
A7: 6 | B7: 19/03/2026 | C7: MARIA LOPEZ | D7: Medellin | E7: Monitor | F7: 0 | G7: 1500 | H7: 0
A8: 7 | B8: 2026-03-01 | C8: Ana Torres | D8: Bogotá | F8: -2 | G8: 1500 | H8: -3000
A9: 8 | B9: 2026-02-14 | C9: MARIA LOPEZ | D9: Bogota | E9: Teclado | F9: -1 | G9: 50 | H9: -50
A10: 9 | B10: 12-Mar-26 | C10: Ana Torres | D10: Medellin | E10: Laptop | F10: 2 | G10: 80 | H10: 160
A11: 10 | B11: 2026-02-01 | C11: juan perez | D11: bogotá | F11: 0 | G11: 80 | H11: 0
A12: 11 | B12: 29/03/2026 | C12: MARIA LOPEZ | D12: Bogotá | F12: -2 | G12: 700 | H12: -1309
A13: 12 | B13: 29-Jan-26 | C13: Carlos Ruiz | D13: bogotá | E13: Laptop | F13: 0 | G13: 700 | H13: 0
A14: 13 | B14: 2026-01-13 | C14: juan perez | D14: bogotá | E14: Laptop | F14: 0 | G14: 50 | H14: 0
A15: 14 | B15: 2026-03-09 | C15: MARIA LOPEZ | D15: Medellin | E15: Mouse | F15: -2 | G15: 80 | H15: -160
A16: 15 | B16: 2026-01-14 | D16: bogotá | E16: Teclado | F16: 5 | G16: 80 | H16: 400
A17: 16 | B17: 2026-01-15 | C17: Carlos Ruiz | D17: Medellin | F17: 0 | G17: 1500 | H17: 0
A18: 17 | B18: 09-Feb-26 | C18: Ana Torres | D18: medellín | E18: Teclado | F18: -3 | G18: 1500 | H18: -4473
A19: 18 | B19: 05-Mar-26 | C19: MARIA LOPEZ | D19: Bogotá | E19: Laptop | F19: 0 | G19: 700 | H19: 0
A20: 19 | B20: 11/02/2026 | D20: Bogota | E20: Teclado | F20: 4 | G20: 700 | H20: 2800
A21: 20 | B21: 2026-01-08 | C21: Ana Torres | D21: Medellin | F21: 4 | G21: 700 | H21: 2800
A22: 21 | B22: 27-Mar-26 | C22: MARIA LOPEZ | D22: Bogota | F22: 0 | G22: 700 | H22: 0
A23: 22 | B23: 07/01/2026 | D23: Medellin | F23: -2 | G23: 700 | H23: -1400
A24: 23 | B24: 13-Jan-26 | C24: Carlos Ruiz | D24: Medellin | E24: Monitor | F24: 5 | G24: 700 | H24: 3522
A25: 24 | B25: 07/03/2026 | C25: Carlos Ruiz | D25: Bogotá | E25: Laptop | F25: -3 | G25: 80 | H25: -240
A26: 25 | B26: 31-Jan-26 | C26: MARIA LOPEZ | D26: Bogotá | E26: Teclado | F26: 0 | G26: 50 | H26: 0
A27: 26 | B27: 13-Feb-26 | D27: Bogotá | F27: 5 | G27: 80 | H27: 400
A28: 27 | B28: 09/01/2026 | C28: Carlos Ruiz | D28: Bogota | F28: -1 | G28: 1500 | H28: -1500
A29: 28 | B29: 25/02/2026 | C29: Ana Torres | D29: bogotá | E29: Mouse | F29: -3 | G29: 1500 | H29: -4500
A30: 29 | B30: 2026-01-22 | C30: juan perez | D30: Bogotá | E30: Mouse | F30: 5 | G30: 700 | H30: 3529
A31: 30 | B31: 09-Jan-26 | C31: MARIA LOPEZ | D31: Medellin | E31: Laptop | F31: 0 | G31: 80 | H31: 0
A32: 31 | B32: 14/02/2026 | C32: Carlos Ruiz | D32: medellín | E32: Laptop | F32: -1 | G32: 1500 | H32: -1500
A33: 32 | B33: 2026-02-19 | C33: MARIA LOPEZ | D33: Bogotá | E33: Monitor | F33: 3 | G33: 1500 | H33: 4521
A34: 33 | B34: 16-Feb-26 | C34: MARIA LOPEZ | D34: Bogota | E34: Mouse | F34: -1 | G34: 1500 | H34: -1500
A35: 34 | B35: 2026-02-04 | C35: Ana Torres | D35: bogotá | E35: Monitor | F35: -3 | G35: 50 | H35: -57
A36: 35 | B36: 2026-03-15 | C36: juan perez | D36: Bogotá | E36: Teclado | F36: -1 | G36: 80 | H36: -80
A37: 36 | B37: 22-Mar-26 | C37: Ana Torres | D37: medellín | F37: 2 | G37: 50 | H37: 100
A38: 37 | B38: 25-Jan-26 | D38: Bogotá | F38: -2 | G38: 1500 | H38: -3000
A39: 38 | B39: 05-Jan-26 | C39: juan perez | D39: Bogotá | F39: 0 | G39: 80 | H39: 16
A40: 39 | B40: 13-Mar-26 | D40: bogotá | E40: Laptop | F40: -3 | G40: 80 | H40: -240
...

Sheet Solucion_Limpia_300
A1: IdVenta | B1: Fecha_Normalizada | C1: Cliente_Limpio | D1: Ciudad_Limpia | E1: Producto_Limpio | F1: Cantidad_Validada | G1: PrecioUnitario | H1: Total_Calculado | I1: Estado_Total
A2: =Dataset_con_Errores!A2 -> 1 | B2: =TEXT(Dataset_con_Errores!B2,"dd/mm/yyyy") -> 05/03/2026 | C2: =IF(Dataset_con_Errores!C2="","Sin Cliente",PROPER(TRIM(Dataset_con_Errores!C2))) -> Ana Torres | D2: =PROPER(TRIM(Dataset_con_Errores!D2)) -> Medellin | E2: =IF(Dataset_con_Errores!E2="","Sin especificar",Dataset_con_Errores!E2) -> Sin especificar | F2: =IF(Dataset_con_Errores!F2<=0,1,Dataset_con_Errores!F2) -> 1 | G2: =Dataset_con_Errores!G2 -> 1500 | H2: =F2*G2 -> 1500 | I2: =IF(H2=Dataset_con_Errores!H2,"OK","ERROR") -> ERROR | J2: =+COUNTIF(Solucion_Limpia_300!I2:I301,"OK") -> 76 | L2: =IFERROR( DATE(RIGHT(B2,4),MID(B2,4,2),LEFT(B2,2)), IFERROR( DATE(LEFT(B2,4),MID(B2,6,2),RIGHT(B2,2)), IFERROR( DATE( 2000+VALUE(RIGHT(B2,2)), MATCH( UPPER(MID(B2,4,3)), {"JAN";"FEB";"MAR";"APR";"MAY";"JUN";"JUL";"AUG";"SEP";"OCT";"NOV";"DEC"}, 0 ), VALUE(LEFT(B2,2)) ), "ERROR") ) ) -> 46086
A3: =Dataset_con_Errores!A3 -> 2 | B3: =TEXT(Dataset_con_Errores!B3,"dd/mm/yyyy") -> 20/03/2026 | C3: =IF(Dataset_con_Errores!C3="","Sin Cliente",PROPER(TRIM(Dataset_con_Errores!C3))) -> Sin Cliente | D3: =PROPER(TRIM(Dataset_con_Errores!D3)) -> Medellín | E3: =IF(Dataset_con_Errores!E3="","Sin especificar",Dataset_con_Errores!E3) -> Laptop | F3: =IF(Dataset_con_Errores!F3<=0,1,Dataset_con_Errores!F3) -> 1 | G3: =Dataset_con_Errores!G3 -> 50 | H3: =F3*G3 -> 50 | I3: =IF(H3=Dataset_con_Errores!H3,"OK","ERROR") -> ERROR | L3: =IFERROR( DATE(RIGHT(B3,4),MID(B3,4,2),LEFT(B3,2)), IFERROR( DATE(LEFT(B3,4),MID(B3,6,2),RIGHT(B3,2)), IFERROR( DATE( 2000+VALUE(RIGHT(B3,2)), MATCH( UPPER(MID(B3,4,3)), {"JAN";"FEB";"MAR";"APR";"MAY";"JUN";"JUL";"AUG";"SEP";"OCT";"NOV";"DEC"}, 0 ), VALUE(LEFT(B3,2)) ), "ERROR") ) ) -> 46101
A4: =Dataset_con_Errores!A4 -> 3 | B4: =TEXT(Dataset_con_Errores!B4,"dd/mm/yyyy") -> 31-Jan-26 | C4: =IF(Dataset_con_Errores!C4="","Sin Cliente",PROPER(TRIM(Dataset_con_Errores!C4))) -> Juan Perez | D4: =PROPER(TRIM(Dataset_con_Errores!D4)) -> Bogotá | E4: =IF(Dataset_con_Errores!E4="","Sin especificar",Dataset_con_Errores!E4) -> Mouse | F4: =IF(Dataset_con_Errores!F4<=0,1,Dataset_con_Errores!F4) -> 1 | G4: =Dataset_con_Errores!G4 -> 1500 | H4: =F4*G4 -> 1500 | I4: =IF(H4=Dataset_con_Errores!H4,"OK","ERROR") -> ERROR | L4: =IFERROR( DATE(RIGHT(B4,4),MID(B4,4,2),LEFT(B4,2)), IFERROR( DATE(LEFT(B4,4),MID(B4,6,2),RIGHT(B4,2)), IFERROR( DATE( 2000+VALUE(RIGHT(B4,2)), MATCH( UPPER(MID(B4,4,3)), {"JAN";"FEB";"MAR";"APR";"MAY";"JUN";"JUL";"AUG";"SEP";"OCT";"NOV";"DEC"}, 0 ), VALUE(LEFT(B4,2)) ), "ERROR") ) ) -> 46053
A5: =Dataset_con_Errores!A5 -> 4 | B5: =TEXT(Dataset_con_Errores!B5,"dd/mm/yyyy") -> 02/01/2026 | C5: =IF(Dataset_con_Errores!C5="","Sin Cliente",PROPER(TRIM(Dataset_con_Errores!C5))) -> Carlos Ruiz | D5: =PROPER(TRIM(Dataset_con_Errores!D5)) -> Bogota | E5: =IF(Dataset_con_Errores!E5="","Sin especificar",Dataset_con_Errores!E5) -> Monitor | F5: =IF(Dataset_con_Errores!F5<=0,1,Dataset_con_Errores!F5) -> 3 | G5: =Dataset_con_Errores!G5 -> 1500 | H5: =F5*G5 -> 4500 | I5: =IF(H5=Dataset_con_Errores!H5,"OK","ERROR") -> OK | L5: =IFERROR( DATE(RIGHT(B5,4),MID(B5,4,2),LEFT(B5,2)), IFERROR( DATE(LEFT(B5,4),MID(B5,6,2),RIGHT(B5,2)), IFERROR( DATE( 2000+VALUE(RIGHT(B5,2)), MATCH( UPPER(MID(B5,4,3)), {"JAN";"FEB";"MAR";"APR";"MAY";"JUN";"JUL";"AUG";"SEP";"OCT";"NOV";"DEC"}, 0 ), VALUE(LEFT(B5,2)) ), "ERROR") ) ) -> 46024
A6: =Dataset_con_Errores!A6 -> 5 | B6: =TEXT(Dataset_con_Errores!B6,"dd/mm/yyyy") -> 06/03/2026 | C6: =IF(Dataset_con_Errores!C6="","Sin Cliente",PROPER(TRIM(Dataset_con_Errores!C6))) -> Maria Lopez | D6: =PROPER(TRIM(Dataset_con_Errores!D6)) -> Medellín | E6: =IF(Dataset_con_Errores!E6="","Sin especificar",Dataset_con_Errores!E6) -> Sin especificar | F6: =IF(Dataset_con_Errores!F6<=0,1,Dataset_con_Errores!F6) -> 1 | G6: =Dataset_con_Errores!G6 -> 50 | H6: =F6*G6 -> 50 | I6: =IF(H6=Dataset_con_Errores!H6,"OK","ERROR") -> ERROR | L6: =IFERROR( DATE(RIGHT(B6,4),MID(B6,4,2),LEFT(B6,2)), IFERROR( DATE(LEFT(B6,4),MID(B6,6,2),RIGHT(B6,2)), IFERROR( DATE( 2000+VALUE(RIGHT(B6,2)), MATCH( UPPER(MID(B6,4,3)), {"JAN";"FEB";"MAR";"APR";"MAY";"JUN";"JUL";"AUG";"SEP";"OCT";"NOV";"DEC"}, 0 ), VALUE(LEFT(B6,2)) ), "ERROR") ) ) -> 46087
A7: =Dataset_con_Errores!A7 -> 6 | B7: =TEXT(Dataset_con_Errores!B7,"dd/mm/yyyy") -> 19/03/2026 | C7: =IF(Dataset_con_Errores!C7="","Sin Cliente",PROPER(TRIM(Dataset_con_Errores!C7))) -> Maria Lopez | D7: =PROPER(TRIM(Dataset_con_Errores!D7)) -> Medellin | E7: =IF(Dataset_con_Errores!E7="","Sin especificar",Dataset_con_Errores!E7) -> Monitor | F7: =IF(Dataset_con_Errores!F7<=0,1,Dataset_con_Errores!F7) -> 1 | G7: =Dataset_con_Errores!G7 -> 1500 | H7: =F7*G7 -> 1500 | I7: =IF(H7=Dataset_con_Errores!H7,"OK","ERROR") -> ERROR | L7: =IFERROR( DATE(RIGHT(B7,4),MID(B7,4,2),LEFT(B7,2)), IFERROR( DATE(LEFT(B7,4),MID(B7,6,2),RIGHT(B7,2)), IFERROR( DATE( 2000+VALUE(RIGHT(B7,2)), MATCH( UPPER(MID(B7,4,3)), {"JAN";"FEB";"MAR";"APR";"MAY";"JUN";"JUL";"AUG";"SEP";"OCT";"NOV";"DEC"}, 0 ), VALUE(LEFT(B7,2)) ), "ERROR") ) ) -> 46100
A8: =Dataset_con_Errores!A8 -> 7 | B8: =TEXT(Dataset_con_Errores!B8,"dd/mm/yyyy") -> 01/03/2026 | C8: =IF(Dataset_con_Errores!C8="","Sin Cliente",PROPER(TRIM(Dataset_con_Errores!C8))) -> Ana Torres | D8: =PROPER(TRIM(Dataset_con_Errores!D8)) -> Bogotá | E8: =IF(Dataset_con_Errores!E8="","Sin especificar",Dataset_con_Errores!E8) -> Sin especificar | F8: =IF(Dataset_con_Errores!F8<=0,1,Dataset_con_Errores!F8) -> 1 | G8: =Dataset_con_Errores!G8 -> 1500 | H8: =F8*G8 -> 1500 | I8: =IF(H8=Dataset_con_Errores!H8,"OK","ERROR") -> ERROR | L8: =IFERROR( DATE(RIGHT(B8,4),MID(B8,4,2),LEFT(B8,2)), IFERROR( DATE(LEFT(B8,4),MID(B8,6,2),RIGHT(B8,2)), IFERROR( DATE( 2000+VALUE(RIGHT(B8,2)), MATCH( UPPER(MID(B8,4,3)), {"JAN";"FEB";"MAR";"APR";"MAY";"JUN";"JUL";"AUG";"SEP";"OCT";"NOV";"DEC"}, 0 ), VALUE(LEFT(B8,2)) ), "ERROR") ) ) -> 46082
A9: =Dataset_con_Errores!A9 -> 8 | B9: =TEXT(Dataset_con_Errores!B9,"dd/mm/yyyy") -> 14/02/2026 | C9: =IF(Dataset_con_Errores!C9="","Sin Cliente",PROPER(TRIM(Dataset_con_Errores!C9))) -> Maria Lopez | D9: =PROPER(TRIM(Dataset_con_Errores!D9)) -> Bogota | E9: =IF(Dataset_con_Errores!E9="","Sin especificar",Dataset_con_Errores!E9) -> Teclado | F9: =IF(Dataset_con_Errores!F9<=0,1,Dataset_con_Errores!F9) -> 1 | G9: =Dataset_con_Errores!G9 -> 50 | H9: =F9*G9 -> 50 | I9: =IF(H9=Dataset_con_Errores!H9,"OK","ERROR") -> ERROR | L9: =IFERROR( DATE(RIGHT(B9,4),MID(B9,4,2),LEFT(B9,2)), IFERROR( DATE(LEFT(B9,4),MID(B9,6,2),RIGHT(B9,2)), IFERROR( DATE( 2000+VALUE(RIGHT(B9,2)), MATCH( UPPER(MID(B9,4,3)), {"JAN";"FEB";"MAR";"APR";"MAY";"JUN";"JUL";"AUG";"SEP";"OCT";"NOV";"DEC"}, 0 ), VALUE(LEFT(B9,2)) ), "ERROR") ) ) -> 46067
A10: =Dataset_con_Errores!A10 -> 9 | B10: =TEXT(Dataset_con_Errores!B10,"dd/mm/yyyy") -> 12/03/2026 | C10: =IF(Dataset_con_Errores!C10="","Sin Cliente",PROPER(TRIM(Dataset_con_Errores!C10))) -> Ana Torres | D10: =PROPER(TRIM(Dataset_con_Errores!D10)) -> Medellin | E10: =IF(Dataset_con_Errores!E10="","Sin especificar",Dataset_con_Errores!E10) -> Laptop | F10: =IF(Dataset_con_Errores!F10<=0,1,Dataset_con_Errores!F10) -> 2 | G10: =Dataset_con_Errores!G10 -> 80 | H10: =F10*G10 -> 160 | I10: =IF(H10=Dataset_con_Errores!H10,"OK","ERROR") -> OK | L10: =IFERROR( DATE(RIGHT(B10,4),MID(B10,4,2),LEFT(B10,2)), IFERROR( DATE(LEFT(B10,4),MID(B10,6,2),RIGHT(B10,2)), IFERROR( DATE( 2000+VALUE(RIGHT(B10,2)), MATCH( UPPER(MID(B10,4,3)), {"JAN";"FEB";"MAR";"APR";"MAY";"JUN";"JUL";"AUG";"SEP";"OCT";"NOV";"DEC"}, 0 ), VALUE(LEFT(B10,2)) ), "ERROR") ) ) -> 46093
A11: =Dataset_con_Errores!A11 -> 10 | B11: =TEXT(Dataset_con_Errores!B11,"dd/mm/yyyy") -> 01/02/2026 | C11: =IF(Dataset_con_Errores!C11="","Sin Cliente",PROPER(TRIM(Dataset_con_Errores!C11))) -> Juan Perez | D11: =PROPER(TRIM(Dataset_con_Errores!D11)) -> Bogotá | E11: =IF(Dataset_con_Errores!E11="","Sin especificar",Dataset_con_Errores!E11) -> Sin especificar | F11: =IF(Dataset_con_Errores!F11<=0,1,Dataset_con_Errores!F11) -> 1 | G11: =Dataset_con_Errores!G11 -> 80 | H11: =F11*G11 -> 80 | I11: =IF(H11=Dataset_con_Errores!H11,"OK","ERROR") -> ERROR | L11: =IFERROR( DATE(RIGHT(B11,4),MID(B11,4,2),LEFT(B11,2)), IFERROR( DATE(LEFT(B11,4),MID(B11,6,2),RIGHT(B11,2)), IFERROR( DATE( 2000+VALUE(RIGHT(B11,2)), MATCH( UPPER(MID(B11,4,3)), {"JAN";"FEB";"MAR";"APR";"MAY";"JUN";"JUL";"AUG";"SEP";"OCT";"NOV";"DEC"}, 0 ), VALUE(LEFT(B11,2)) ), "ERROR") ) ) -> 46054
A12: =Dataset_con_Errores!A12 -> 11 | B12: =TEXT(Dataset_con_Errores!B12,"dd/mm/yyyy") -> 29/03/2026 | C12: =IF(Dataset_con_Errores!C12="","Sin Cliente",PROPER(TRIM(Dataset_con_Errores!C12))) -> Maria Lopez | D12: =PROPER(TRIM(Dataset_con_Errores!D12)) -> Bogotá | E12: =IF(Dataset_con_Errores!E12="","Sin especificar",Dataset_con_Errores!E12) -> Sin especificar | F12: =IF(Dataset_con_Errores!F12<=0,1,Dataset_con_Errores!F12) -> 1 | G12: =Dataset_con_Errores!G12 -> 700 | H12: =F12*G12 -> 700 | I12: =IF(H12=Dataset_con_Errores!H12,"OK","ERROR") -> ERROR | L12: =IFERROR( DATE(RIGHT(B12,4),MID(B12,4,2),LEFT(B12,2)), IFERROR( DATE(LEFT(B12,4),MID(B12,6,2),RIGHT(B12,2)), IFERROR( DATE( 2000+VALUE(RIGHT(B12,2)), MATCH( UPPER(MID(B12,4,3)), {"JAN";"FEB";"MAR";"APR";"MAY";"JUN";"JUL";"AUG";"SEP";"OCT";"NOV";"DEC"}, 0 ), VALUE(LEFT(B12,2)) ), "ERROR") ) ) -> 46110
A13: =Dataset_con_Errores!A13 -> 12 | B13: =TEXT(Dataset_con_Errores!B13,"dd/mm/yyyy") -> 29-Jan-26 | C13: =IF(Dataset_con_Errores!C13="","Sin Cliente",PROPER(TRIM(Dataset_con_Errores!C13))) -> Carlos Ruiz | D13: =PROPER(TRIM(Dataset_con_Errores!D13)) -> Bogotá | E13: =IF(Dataset_con_Errores!E13="","Sin especificar",Dataset_con_Errores!E13) -> Laptop | F13: =IF(Dataset_con_Errores!F13<=0,1,Dataset_con_Errores!F13) -> 1 | G13: =Dataset_con_Errores!G13 -> 700 | H13: =F13*G13 -> 700 | I13: =IF(H13=Dataset_con_Errores!H13,"OK","ERROR") -> ERROR | L13: =IFERROR( DATE(RIGHT(B13,4),MID(B13,4,2),LEFT(B13,2)), IFERROR( DATE(LEFT(B13,4),MID(B13,6,2),RIGHT(B13,2)), IFERROR( DATE( 2000+VALUE(RIGHT(B13,2)), MATCH( UPPER(MID(B13,4,3)), {"JAN";"FEB";"MAR";"APR";"MAY";"JUN";"JUL";"AUG";"SEP";"OCT";"NOV";"DEC"}, 0 ), VALUE(LEFT(B13,2)) ), "ERROR") ) ) -> 46051
A14: =Dataset_con_Errores!A14 -> 13 | B14: =TEXT(Dataset_con_Errores!B14,"dd/mm/yyyy") -> 13/01/2026 | C14: =IF(Dataset_con_Errores!C14="","Sin Cliente",PROPER(TRIM(Dataset_con_Errores!C14))) -> Juan Perez | D14: =PROPER(TRIM(Dataset_con_Errores!D14)) -> Bogotá | E14: =IF(Dataset_con_Errores!E14="","Sin especificar",Dataset_con_Errores!E14) -> Laptop | F14: =IF(Dataset_con_Errores!F14<=0,1,Dataset_con_Errores!F14) -> 1 | G14: =Dataset_con_Errores!G14 -> 50 | H14: =F14*G14 -> 50 | I14: =IF(H14=Dataset_con_Errores!H14,"OK","ERROR") -> ERROR | L14: =IFERROR( DATE(RIGHT(B14,4),MID(B14,4,2),LEFT(B14,2)), IFERROR( DATE(LEFT(B14,4),MID(B14,6,2),RIGHT(B14,2)), IFERROR( DATE( 2000+VALUE(RIGHT(B14,2)), MATCH( UPPER(MID(B14,4,3)), {"JAN";"FEB";"MAR";"APR";"MAY";"JUN";"JUL";"AUG";"SEP";"OCT";"NOV";"DEC"}, 0 ), VALUE(LEFT(B14,2)) ), "ERROR") ) ) -> 46035
A15: =Dataset_con_Errores!A15 -> 14 | B15: =TEXT(Dataset_con_Errores!B15,"dd/mm/yyyy") -> 09/03/2026 | C15: =IF(Dataset_con_Errores!C15="","Sin Cliente",PROPER(TRIM(Dataset_con_Errores!C15))) -> Maria Lopez | D15: =PROPER(TRIM(Dataset_con_Errores!D15)) -> Medellin | E15: =IF(Dataset_con_Errores!E15="","Sin especificar",Dataset_con_Errores!E15) -> Mouse | F15: =IF(Dataset_con_Errores!F15<=0,1,Dataset_con_Errores!F15) -> 1 | G15: =Dataset_con_Errores!G15 -> 80 | H15: =F15*G15 -> 80 | I15: =IF(H15=Dataset_con_Errores!H15,"OK","ERROR") -> ERROR
A16: =Dataset_con_Errores!A16 -> 15 | B16: =TEXT(Dataset_con_Errores!B16,"dd/mm/yyyy") -> 14/01/2026 | C16: =IF(Dataset_con_Errores!C16="","Sin Cliente",PROPER(TRIM(Dataset_con_Errores!C16))) -> Sin Cliente | D16: =PROPER(TRIM(Dataset_con_Errores!D16)) -> Bogotá | E16: =IF(Dataset_con_Errores!E16="","Sin especificar",Dataset_con_Errores!E16) -> Teclado | F16: =IF(Dataset_con_Errores!F16<=0,1,Dataset_con_Errores!F16) -> 5 | G16: =Dataset_con_Errores!G16 -> 80 | H16: =F16*G16 -> 400 | I16: =IF(H16=Dataset_con_Errores!H16,"OK","ERROR") -> OK
A17: =Dataset_con_Errores!A17 -> 16 | B17: =TEXT(Dataset_con_Errores!B17,"dd/mm/yyyy") -> 15/01/2026 | C17: =IF(Dataset_con_Errores!C17="","Sin Cliente",PROPER(TRIM(Dataset_con_Errores!C17))) -> Carlos Ruiz | D17: =PROPER(TRIM(Dataset_con_Errores!D17)) -> Medellin | E17: =IF(Dataset_con_Errores!E17="","Sin especificar",Dataset_con_Errores!E17) -> Sin especificar | F17: =IF(Dataset_con_Errores!F17<=0,1,Dataset_con_Errores!F17) -> 1 | G17: =Dataset_con_Errores!G17 -> 1500 | H17: =F17*G17 -> 1500 | I17: =IF(H17=Dataset_con_Errores!H17,"OK","ERROR") -> ERROR
A18: =Dataset_con_Errores!A18 -> 17 | B18: =TEXT(Dataset_con_Errores!B18,"dd/mm/yyyy") -> 09/02/2026 | C18: =IF(Dataset_con_Errores!C18="","Sin Cliente",PROPER(TRIM(Dataset_con_Errores!C18))) -> Ana Torres | D18: =PROPER(TRIM(Dataset_con_Errores!D18)) -> Medellín | E18: =IF(Dataset_con_Errores!E18="","Sin especificar",Dataset_con_Errores!E18) -> Teclado | F18: =IF(Dataset_con_Errores!F18<=0,1,Dataset_con_Errores!F18) -> 1 | G18: =Dataset_con_Errores!G18 -> 1500 | H18: =F18*G18 -> 1500 | I18: =IF(H18=Dataset_con_Errores!H18,"OK","ERROR") -> ERROR
A19: =Dataset_con_Errores!A19 -> 18 | B19: =TEXT(Dataset_con_Errores!B19,"dd/mm/yyyy") -> 05/03/2026 | C19: =IF(Dataset_con_Errores!C19="","Sin Cliente",PROPER(TRIM(Dataset_con_Errores!C19))) -> Maria Lopez | D19: =PROPER(TRIM(Dataset_con_Errores!D19)) -> Bogotá | E19: =IF(Dataset_con_Errores!E19="","Sin especificar",Dataset_con_Errores!E19) -> Laptop | F19: =IF(Dataset_con_Errores!F19<=0,1,Dataset_con_Errores!F19) -> 1 | G19: =Dataset_con_Errores!G19 -> 700 | H19: =F19*G19 -> 700 | I19: =IF(H19=Dataset_con_Errores!H19,"OK","ERROR") -> ERROR
A20: =Dataset_con_Errores!A20 -> 19 | B20: =TEXT(Dataset_con_Errores!B20,"dd/mm/yyyy") -> 11/02/2026 | C20: =IF(Dataset_con_Errores!C20="","Sin Cliente",PROPER(TRIM(Dataset_con_Errores!C20))) -> Sin Cliente | D20: =PROPER(TRIM(Dataset_con_Errores!D20)) -> Bogota | E20: =IF(Dataset_con_Errores!E20="","Sin especificar",Dataset_con_Errores!E20) -> Teclado | F20: =IF(Dataset_con_Errores!F20<=0,1,Dataset_con_Errores!F20) -> 4 | G20: =Dataset_con_Errores!G20 -> 700 | H20: =F20*G20 -> 2800 | I20: =IF(H20=Dataset_con_Errores!H20,"OK","ERROR") -> OK
A21: =Dataset_con_Errores!A21 -> 20 | B21: =TEXT(Dataset_con_Errores!B21,"dd/mm/yyyy") -> 08/01/2026 | C21: =IF(Dataset_con_Errores!C21="","Sin Cliente",PROPER(TRIM(Dataset_con_Errores!C21))) -> Ana Torres | D21: =PROPER(TRIM(Dataset_con_Errores!D21)) -> Medellin | E21: =IF(Dataset_con_Errores!E21="","Sin especificar",Dataset_con_Errores!E21) -> Sin especificar | F21: =IF(Dataset_con_Errores!F21<=0,1,Dataset_con_Errores!F21) -> 4 | G21: =Dataset_con_Errores!G21 -> 700 | H21: =F21*G21 -> 2800 | I21: =IF(H21=Dataset_con_Errores!H21,"OK","ERROR") -> OK
A22: =Dataset_con_Errores!A22 -> 21 | B22: =TEXT(Dataset_con_Errores!B22,"dd/mm/yyyy") -> 27/03/2026 | C22: =IF(Dataset_con_Errores!C22="","Sin Cliente",PROPER(TRIM(Dataset_con_Errores!C22))) -> Maria Lopez | D22: =PROPER(TRIM(Dataset_con_Errores!D22)) -> Bogota | E22: =IF(Dataset_con_Errores!E22="","Sin especificar",Dataset_con_Errores!E22) -> Sin especificar | F22: =IF(Dataset_con_Errores!F22<=0,1,Dataset_con_Errores!F22) -> 1 | G22: =Dataset_con_Errores!G22 -> 700 | H22: =F22*G22 -> 700 | I22: =IF(H22=Dataset_con_Errores!H22,"OK","ERROR") -> ERROR
A23: =Dataset_con_Errores!A23 -> 22 | B23: =TEXT(Dataset_con_Errores!B23,"dd/mm/yyyy") -> 07/01/2026 | C23: =IF(Dataset_con_Errores!C23="","Sin Cliente",PROPER(TRIM(Dataset_con_Errores!C23))) -> Sin Cliente | D23: =PROPER(TRIM(Dataset_con_Errores!D23)) -> Medellin | E23: =IF(Dataset_con_Errores!E23="","Sin especificar",Dataset_con_Errores!E23) -> Sin especificar | F23: =IF(Dataset_con_Errores!F23<=0,1,Dataset_con_Errores!F23) -> 1 | G23: =Dataset_con_Errores!G23 -> 700 | H23: =F23*G23 -> 700 | I23: =IF(H23=Dataset_con_Errores!H23,"OK","ERROR") -> ERROR
A24: =Dataset_con_Errores!A24 -> 23 | B24: =TEXT(Dataset_con_Errores!B24,"dd/mm/yyyy") -> 13-Jan-26 | C24: =IF(Dataset_con_Errores!C24="","Sin Cliente",PROPER(TRIM(Dataset_con_Errores!C24))) -> Carlos Ruiz | D24: =PROPER(TRIM(Dataset_con_Errores!D24)) -> Medellin | E24: =IF(Dataset_con_Errores!E24="","Sin especificar",Dataset_con_Errores!E24) -> Monitor | F24: =IF(Dataset_con_Errores!F24<=0,1,Dataset_con_Errores!F24) -> 5 | G24: =Dataset_con_Errores!G24 -> 700 | H24: =F24*G24 -> 3500 | I24: =IF(H24=Dataset_con_Errores!H24,"OK","ERROR") -> ERROR
A25: =Dataset_con_Errores!A25 -> 24 | B25: =TEXT(Dataset_con_Errores!B25,"dd/mm/yyyy") -> 07/03/2026 | C25: =IF(Dataset_con_Errores!C25="","Sin Cliente",PROPER(TRIM(Dataset_con_Errores!C25))) -> Carlos Ruiz | D25: =PROPER(TRIM(Dataset_con_Errores!D25)) -> Bogotá | E25: =IF(Dataset_con_Errores!E25="","Sin especificar",Dataset_con_Errores!E25) -> Laptop | F25: =IF(Dataset_con_Errores!F25<=0,1,Dataset_con_Errores!F25) -> 1 | G25: =Dataset_con_Errores!G25 -> 80 | H25: =F25*G25 -> 80 | I25: =IF(H25=Dataset_con_Errores!H25,"OK","ERROR") -> ERROR
A26: =Dataset_con_Errores!A26 -> 25 | B26: =TEXT(Dataset_con_Errores!B26,"dd/mm/yyyy") -> 31-Jan-26 | C26: =IF(Dataset_con_Errores!C26="","Sin Cliente",PROPER(TRIM(Dataset_con_Errores!C26))) -> Maria Lopez | D26: =PROPER(TRIM(Dataset_con_Errores!D26)) -> Bogotá | E26: =IF(Dataset_con_Errores!E26="","Sin especificar",Dataset_con_Errores!E26) -> Teclado | F26: =IF(Dataset_con_Errores!F26<=0,1,Dataset_con_Errores!F26) -> 1 | G26: =Dataset_con_Errores!G26 -> 50 | H26: =F26*G26 -> 50 | I26: =IF(H26=Dataset_con_Errores!H26,"OK","ERROR") -> ERROR
... A301: =Dataset_con_Errores!A301 -> 300 | B301: =TEXT(Dataset_con_Errores!B301,"dd/mm/yyyy") -> 21-Jan-26 | C301: =IF(Dataset_con_Errores!C301="","Sin Cliente",PROPER(TRIM(Dataset_con_Errores!C301))) -> Juan Perez | D301: =PROPER(TRIM(Dataset_con_Errores!D301)) -> Bogota | E301: =IF(Dataset_con_Errores!E301="","Sin especificar",Dataset_con_Errores!E301) -> Laptop | F301: =IF(Dataset_con_Errores!F301<=0,1,Dataset_con_Errores!F301) -> 3 | G301: =Dataset_con_Errores!G301 -> 80 | H301: =F301*G301 -> 240 | I301: =IF(H301=Dataset_con_Errores!H301,"OK","ERROR") -> OK

Sheet KPIs_Calidad
A1: Métrica | B1: Valor
A2: Total Registros | B2: =COUNTA(Dataset_con_Errores!A2:A301) -> 300
A3: Cantidad Inválida | B3: =COUNTIF(Dataset_con_Errores!F2:F301,"<=0") -> 200
A4: Total Incorrecto | B4: =COUNTIF(Solucion_Limpia_300!I2:I301,"ERROR") -> 224
A5: Cliente Vacío | B5: =COUNTIF(Dataset_con_Errores!C2:C301,"") -> 56
A6: % Error Total | B6: =B4/B2 -> 0.74666667

Sheet Dashboard
A1: Indicadores de Calidad de Datos
A3: Cantidad Inválida | B3: =KPIs_Calidad!B3 -> 200
A4: Total Incorrecto | B4: =KPIs_Calidad!B4 -> 224
A5: Cliente Vacío | B5: =KPIs_Calidad!B5 -> 56

Sheet Rubrica_Taller
A1: Criterio | B1: Puntaje Máximo
A2: Identificación de errores | B2: 20
A3: Estandarización de datos | B3: 20
A4: Corrección con fórmulas | B4: 20
A5: Cálculo de KPIs | B5: 20
A6: Construcción de Dashboard | B6: 20
A7: Total | B7: 100
